<?xml version="1.0" encoding="utf-8"?>
<!-- This URDF was automatically created by SolidWorks to URDF Exporter! Originally created by Stephen Brawner (brawner@gmail.com) 
     Commit Version: 1.6.0-4-g7f85cfe  Build Version: 1.6.7995.38578
     For more information, please see http://wiki.ros.org/sw_urdf_exporter -->
<robot
  name="robot_arm_simulation">
  <link
    name="base_link">
    <inertial>
      <origin
        xyz="0.00106636629393505 -0.0293070547501314 -0.0202271384386062"
        rpy="0 0 0" />
      <mass
        value="0.181232960202139" />
      <inertia
        ixx="0.000378119657215816"
        ixy="3.43630639396438E-08"
        ixz="1.2081423121706E-08"
        iyy="0.000223474959293216"
        iyz="-3.05424708977584E-08"
        izz="0.000529739128883702" />
    </inertial>
    <visual>
      <origin
        xyz="0 0 0"
        rpy="0 0 0" />
      <geometry>
        <mesh
          filename="package://robot_arm_simulation/meshes/base_link.STL" />
      </geometry>
      <material
        name="">
        <color
          rgba="1 1 1 1" />
      </material>
    </visual>
    <collision>
      <origin
        xyz="0 0 0"
        rpy="0 0 0" />
      <geometry>
        <mesh
          filename="package://robot_arm_simulation/meshes/base_link.STL" />
      </geometry>
    </collision>
  </link>
  <link
    name="link0">
    <inertial>
      <origin
        xyz="0.0111890887322725 7.95670400899548E-05 0.0214102523586093"
        rpy="0 0 0" />
      <mass
        value="0.879776233355334" />
      <inertia
        ixx="0.000862763875907959"
        ixy="6.15528323430402E-07"
        ixz="-3.96090868703226E-05"
        iyy="0.00403893616113799"
        iyz="4.5201151064285E-07"
        izz="0.00478940769522656" />
    </inertial>
    <visual>
      <origin
        xyz="0 0 0"
        rpy="0 0 0" />
      <geometry>
        <mesh
          filename="package://robot_arm_simulation/meshes/link0.STL" />
      </geometry>
      <material
        name="">
        <color
          rgba="1 1 1 1" />
      </material>
    </visual>
    <collision>
      <origin
        xyz="0 0 0"
        rpy="0 0 0" />
      <geometry>
        <mesh
          filename="package://robot_arm_simulation/meshes/link0.STL" />
      </geometry>
    </collision>
  </link>
  <joint
    name="joint0"
    type="revolute">
    <origin
      xyz="0.00106821443596945 -0.0292999484608107 0.00800400717471925"
      rpy="0 0 0" />
    <parent
      link="base_link" />
    <child
      link="link0" />
    <axis
      xyz="0 0 -1" />
    <limit
      lower="-3.14"
      upper="3.14"
      effort="0"
      velocity="0" />
  </joint>
  <link
    name="link1">
    <inertial>
      <origin
        xyz="0.00281617747478818 0.0187461142617349 0.0803848783888099"
        rpy="0 0 0" />
      <mass
        value="0.305120412259981" />
      <inertia
        ixx="0.000603655935467257"
        ixy="1.75785098932972E-05"
        ixz="3.50259615822114E-05"
        iyy="0.000541484333663019"
        iyz="-5.95559669429248E-05"
        izz="0.000485737263645997" />
    </inertial>
    <visual>
      <origin
        xyz="0 0 0"
        rpy="0 0 0" />
      <geometry>
        <mesh
          filename="package://robot_arm_simulation/meshes/link1.STL" />
      </geometry>
      <material
        name="">
        <color
          rgba="1 1 1 1" />
      </material>
    </visual>
    <collision>
      <origin
        xyz="0 0 0"
        rpy="0 0 0" />
      <geometry>
        <mesh
          filename="package://robot_arm_simulation/meshes/link1.STL" />
      </geometry>
    </collision>
  </link>
  <joint
    name="joint1"
    type="revolute">
    <origin
      xyz="0.25 0 -0.00150000000000016"
      rpy="0 0 0" />
    <parent
      link="link0" />
    <child
      link="link1" />
    <axis
      xyz="0 0 -1" />
    <limit
      lower="-2.5730"
      upper="2.5730"
      effort="0"
      velocity="0" />
  </joint>
  <link
    name="link2">
    <inertial>
      <origin
        xyz="0.190000000000004 -3.88578058618805E-16 0.00570000000000492"
        rpy="0 0 0" />
      <mass
        value="0.00120144062508099" />
      <inertia
        ixx="3.01098397352896E-09"
        ixy="-2.55392014125747E-23"
        ixz="-5.66282845613959E-24"
        iyy="3.01098397352889E-09"
        iyz="-2.19537552223302E-24"
        izz="2.81812628017522E-09" />
    </inertial>
    <visual>
      <origin
        xyz="0 0 0"
        rpy="0 0 0" />
      <geometry>
        <mesh
          filename="package://robot_arm_simulation/meshes/link2.STL" />
      </geometry>
      <material
        name="">
        <color
          rgba="0.956862745098039 0.956862745098039 0.96078431372549 1" />
      </material>
    </visual>
    <collision>
      <origin
        xyz="0 0 0"
        rpy="0 0 0" />
      <geometry>
        <mesh
          filename="package://robot_arm_simulation/meshes/link2.STL" />
      </geometry>
    </collision>
  </link>
  <joint
    name="joint2"
    type="revolute">
    <origin
      xyz="0 0.0612999999999991 0.0969999999999984"
      rpy="1.5707963267949 -0.870669676164259 3.14159265358979" />
    <parent
      link="link1" />
    <child
      link="link2" />
    <axis
      xyz="0 0 -1" />
    <limit
      lower="-2.0933"
      upper="0.7762"
      effort="0"
      velocity="0" />
  </joint>
  <link
    name="link3">
    <inertial>
      <origin
        xyz="0.062006399403465 -0.00325003674916025 0.0632250133882652"
        rpy="0 0 0" />
      <mass
        value="0.536763198214733" />
      <inertia
        ixx="0.00123232179572037"
        ixy="9.2314357372612E-06"
        ixz="-0.000550953767983446"
        iyy="0.00271071392480847"
        iyz="1.28365579081404E-05"
        izz="0.0022399403251366" />
    </inertial>
    <visual>
      <origin
        xyz="0 0 0"
        rpy="0 0 0" />
      <geometry>
        <mesh
          filename="package://robot_arm_simulation/meshes/link3.STL" />
      </geometry>
      <material
        name="">
        <color
          rgba="1 1 1 1" />
      </material>
    </visual>
    <collision>
      <origin
        xyz="0 0 0"
        rpy="0 0 0" />
      <geometry>
        <mesh
          filename="package://robot_arm_simulation/meshes/link3.STL" />
      </geometry>
    </collision>
  </link>
  <joint
    name="joint3"
    type="revolute">
    <origin
      xyz="0.380000000000003 0 -0.000800000000014886"
      rpy="-3.14159265358979 0 2.27092297742553" />
    <parent
      link="link2" />
    <child
      link="link3" />
    <axis
      xyz="0 0 1" />
    <limit
      lower="-0.7762"
      upper="1.0921"
      effort="0"
      velocity="0" />
  </joint>
  <link
    name="link4">
    <inertial>
      <origin
        xyz="-1.06914163189309E-07 -0.0450249174201101 0.217000395801011"
        rpy="0 0 0" />
      <mass
        value="0.000706713940655294" />
      <inertia
        ixx="8.87478674239916E-08"
        ixy="-3.03366369960365E-15"
        ixz="2.14783082624719E-14"
        iyy="1.77314734251676E-07"
        iyz="2.51871944610431E-12"
        izz="8.87489535130983E-08" />
    </inertial>
    <visual>
      <origin
        xyz="0 0 0"
        rpy="0 0 0" />
      <geometry>
        <mesh
          filename="package://robot_arm_simulation/meshes/link4.STL" />
      </geometry>
      <material
        name="">
        <color
          rgba="0.956862745098039 0.956862745098039 0.96078431372549 1" />
      </material>
    </visual>
    <collision>
      <origin
        xyz="0 0 0"
        rpy="0 0 0" />
      <geometry>
        <mesh
          filename="package://robot_arm_simulation/meshes/link4.STL" />
      </geometry>
    </collision>
  </link>
  <joint
    name="joint4"
    type="revolute">
    <origin
      xyz="0.170925093942183 -0.00673187074768322 0.0605000000000014"
      rpy="1.57079632679489 0 1.85877565337396" />
    <parent
      link="link3" />
    <child
      link="link4" />
    <axis
      xyz="0 0 1" />
    <limit
      lower="-3.14"
      upper="3.14"
      effort="0"
      velocity="0" />
  </joint>
  <link
    name="link5">
    <inertial>
      <origin
        xyz="0.00116772554274452 1.35911570886549E-09 0.00192542639535063"
        rpy="0 0 0" />
      <mass
        value="0.0110671010673828" />
      <inertia
        ixx="7.41946836618334E-06"
        ixy="4.01153584298785E-14"
        ixz="1.55740108995894E-07"
        iyy="5.76159957745065E-06"
        iyz="-2.3060877335296E-13"
        izz="1.99830471370586E-06" />
    </inertial>
    <visual>
      <origin
        xyz="0 0 0"
        rpy="0 0 0" />
      <geometry>
        <mesh
          filename="package://robot_arm_simulation/meshes/link5.STL" />
      </geometry>
      <material
        name="">
        <color
          rgba="0.956862745098039 0.956862745098039 0.96078431372549 1" />
      </material>
    </visual>
    <collision>
      <origin
        xyz="0 0 0"
        rpy="0 0 0" />
      <geometry>
        <mesh
          filename="package://robot_arm_simulation/meshes/link5.STL" />
      </geometry>
    </collision>
  </link>
  <joint
    name="joint5"
    type="revolute">
    <origin
      xyz="0 -0.00100000000001002 0.216999999999999"
      rpy="1.5707963267949 -1.5707963267949 0" />
    <parent
      link="link4" />
    <child
      link="link5" />
    <axis
      xyz="0 0 -1" />
    <limit
      lower="-1.57"
      upper="1.57"
      effort="0"
      velocity="0" />
  </joint>
  <link
    name="link6">
    <inertial>
      <origin
        xyz="-4.4203297064338E-09 7.20313475532919E-10 0.022185925556943"
        rpy="0 0 0" />
      <mass
        value="0.0648590877011986" />
      <inertia
        ixx="1.76892288196296E-05"
        ixy="6.85681399282109E-09"
        ixz="5.19824027110117E-13"
        iyy="1.77097922285405E-05"
        iyz="3.49961277322789E-13"
        izz="2.88930432119029E-05" />
    </inertial>
    <visual>
      <origin
        xyz="0 0 0"
        rpy="0 0 0" />
      <geometry>
        <mesh
          filename="package://robot_arm_simulation/meshes/link6.STL" />
      </geometry>
      <material
        name="">
        <color
          rgba="1 1 1 1" />
      </material>
    </visual>
    <collision>
      <origin
        xyz="0 0 0"
        rpy="0 0 0" />
      <geometry>
        <mesh
          filename="package://robot_arm_simulation/meshes/link6.STL" />
      </geometry>
    </collision>
  </link>
  <joint
    name="joint6"
    type="revolute">
    <origin
      xyz="0 0 0"
      rpy="3.14159265358979 -1.5707963267949 0" />
    <parent
      link="link5" />
    <child
      link="link6" />
    <axis
      xyz="0 0 -1" />
    <limit
      lower="-3.14"
      upper="3.14"
      effort="0"
      velocity="0" />
  </joint>
</robot>
